<mujoco>
<default>
   <joint axis="0 0 1" limited="true" range="-90 90" damping="0.3"/>
   <geom size=".1 .1 .1" type="box"/>
</default>

<worldbody>
  <composite type="grid" count="9 9 1" spacing="0.05" offset="0 0 1">
      <skin inflate="0.001" subgrid="3" texcoord="true"/>
      <geom size=".02"/>
    </composite>
   <body>
      <joint name="joint1"/>
      <geom/>
   </body>
   <body pos=".3 0 0">
      <joint name="joint2"/>
      <geom/>
   </body>
</worldbody>

<actuator>
   <general name="unclamped" joint="joint1" gainprm="1" biastype="affine"
      biasprm="0 -1" dyntype="integrator"/>
   <intvelocity name="clamped" joint="joint2" actrange="-1.57 1.57"/>
</actuator>
</mujoco>


<!-- <mujoco>
  <default class="main">
    <geom rgba="1 0 0 1"/>
    <default class="sub">
      <geom rgba="0 1 0 1"/>
    </default>
  </default>

<worldbody>
  <composite type="grid" count="9 9 1" spacing="0.05" offset="0 0 1">
    <skin inflate="0.001" subgrid="3" texcoord="true"/>
    <geom size=".02"/>
    <joint name="pin_0" coord="0 0"/>
    <joint name="pin_1" coord="8 0"/>
  </composite>

<geom type="plane" size="1 1 0.1" rgba=".9 0 0 1"/>
</worldbody>

</mujoco> -->